Workbook
Name TC: Acopios!$N$55

Sheet Resumen
O1: TC | P1: 39.5
B2: Contrato - Moneda original
C4: Contrato | H4: Obra constructora pesos
C5: Obra constructora pesos | D5: 446784590 | E5: =+D5/42 -> 10637728
C6: Obra constructora USD Plaza | D6: 637404 | H6: Contrato | I6: 446784590 | J6: 1
C7: Obra constructora USD CIF | D7: 451303 | H7: Acopio | I7: =+J7*$I$6 -> 22339230 | J7: 0.05
H8: Garantía | I8: =+J8*$I$6 -> 22339230 | J8: 0.05
H9: Canje unidades | I9: =+J9*$I$6 -> 11169615 | J9: 0.025
C10: Acopios
C11: Obra constructora pesos | D11: Acopio 1 | E11: 0.02 | F11: =+E11*D5 -> 8935691.8 | H11: Obra constructora USD Plaza
D12: Acopio 2 | E12: 0.015 | F12: =+E12*D5 -> 6701768.8
D13: Acopio 3 | E13: 0.015 | F13: =+E13*D5 -> 6701768.8 | H13: Contrato | I13: 637404 | J13: 1
C14: Total | E14: =+SUM(E11:E13) -> 0.05 | F14: =+SUM(F11:F13) -> 22339230 | H14: Acopio | I14: =+J14*$I$13 -> 31870.2 | J14: 0.05
C15: Obra constructora USD Plaza | D15: Acopio 1 | E15: 0.02 | F15: =+E15+D6 -> 637404.02 | H15: Garantía | I15: =+J15*$I$13 -> 31870.2 | J15: 0.05
D16: Acopio 2 | E16: 0.015 | F16: =+E16*D6 -> 9561.06 | H16: Canje unidades | I16: =+J16*$I$13 -> 15935.1 | J16: 0.025
D17: Acopio 3 | E17: 0.015 | F17: =+E17*D6 -> 9561.06
C18: Total | E18: =+SUM(E15:E17) -> 0.05 | F18: =+SUM(F15:F17) -> 656526.14 | H18: Obra constructora USD CIF
C19: Obra constructora USD CIF | D19: Acopio 1 | E19: 0.02 | F19: =+E19*D7 -> 9026.06
D20: Acopio 2 | E20: 0.015 | F20: =+E20*D7 -> 6769.545 | H20: Contrato | I20: 451303 | J20: 1
D21: Acopio 3 | E21: 0.015 | F21: =+E21*D7 -> 6769.545 | H21: Acopio | I21: =+J21*$I$20 -> 22565.15 | J21: 0.05
C22: Total | E22: =+SUM(E19:E21) -> 0.05 | F22: =+SUM(F19:F21) -> 22565.15 | H22: Garantía | I22: =+J22*$I$20 -> 22565.15 | J22: 0.05
H23: Canje unidades | I23: =+J23*$I$20 -> 11282.575 | J23: 0.025
C25: Garantía
C26: Obra constructora pesos | D26: 0.05 | E26: =+$D$26*D5 -> 22339230
C27: Obra constructora USD Plaza | E27: =+$D$26*D6 -> 31870.2
C28: Obra constructora USD CIF | E28: =+$D$26*D7 -> 22565.15
C31: Canje unidades
C32: Obra constructora pesos | D32: 0.025 | E32: =+$D$32*D5 -> 11169615
C33: Obra constructora USD Plaza | E33: =+$D$32*D6 -> 15935.1
C34: Obra constructora USD CIF | E34: =+$D$32*D7 -> 11282.575
B38: Contrato - USD
C40: Contrato | H40: Obra constructora pesos
C41: Obra constructora pesos | D41: =+D5/P1 -> 11311002
C42: Obra constructora USD Plaza | D42: 637404 | H42: Contrato | I42: =+D41 -> 11311002 | J42: 1
C43: Obra constructora USD CIF | D43: 451303 | H43: Acopio | I43: =+J43*$I$42 -> 565550.11 | J43: 0.05
D44: =+D41+D42+D43 -> 12399709 | H44: Garantía | I44: =+J44*$I$42 -> 565550.11 | J44: 0.05
H45: Canje unidades | I45: =+J45*$I$42 -> 282775.06 | J45: 0.025
C46: Acopios
C47: Obra constructora pesos | D47: Acopio 1 | E47: 0.02 | F47: =+E47*D41 -> 226220.05 | H47: Obra constructora USD Plaza
D48: Acopio 2 | E48: 0.015 | F48: =+E48*D41 -> 169665.03
...

Sheet Acopios
AJ1: TC | AK1: 38.792
B2: ETAPA 1
B4: Pagos acopio y cálculo % desacopio | M4: Acopio utilizado y saldo
B6: Concepto | D6: Montos contratados | E6: Acopio pago | F6: 0.02 | G6: Fecha pago | H6: Acumulado a la fecha | I6: Saldo a la fecha | J6: Nuevo % desacopio | K6: OP GP | N6: Montos contratados | O6: Acopio 1 | P6: Acopio 2 | Q6: Acopio 3 | R6: Total pago acopio | S6: Desacopio 1 | T6: Desacopio 2 | U6: Desacopio 3 | V6: Total desacopiado | W6: Saldo acopio | X6: Total desacopiado | Y6: Saldo acopio
B7: Acopio 1 (2%) | C7: Obra pesos | D7: 446784590 | E7: =+D7*$F$6 -> 8935691.8 | G7: 45805 | H7: =+'Básico $'!F4+'Básico $'!F5+'Básico $'!F6+'Básico $'!F7+'Básico $'!F8 -> 34963151 | I7: =+D7-H7 -> 411821439 | J7: =+E7/I7 -> 0.021697976 | K7: 048 | M7: Obra pesos | N7: 446784590 | O7: =+N7*$F$6 -> 8935691.8 | P7: 6701768.8 | Q7: 6701768.8 | R7: =+O7+P7+Q7 -> 22339230 | S7: =+'Básico $'!I25 -> 5058742.4 | T7: =+'Básico $'!J25 -> 2377011.1 | U7: =+'Básico $'!K25 -> 1200403.4 | V7: =+S7+T7+U7 -> 8636156.9 | W7: =+R7-V7 -> 13703073 | X7: =+V7/$R$7 -> 0.38659153 | Y7: =+W7/$R$7 -> 0.61340847
C8: Obra USD | D8: 637404 | E8: =+D8*$F$6 -> 12748.08 | H8: 0 | I8: =+D8-H8 -> 637404 | J8: =+E8/I8 -> 0.02 | M8: Obra USD Plaza | N8: 637404 | O8: =+N8*$F$6 -> 12748.08 | P8: 9561.06 | Q8: 9561.06 | R8: =+O8+P8+Q8 -> 31870.2 | S8: =+'Básico USD Plaza'!I10 -> 3865.2984 | T8: =+'Básico USD Plaza'!J10 -> 2898.9738 | U8: =+'Básico USD Plaza'!K10 -> 2715.5984 | V8: =+S8+T8+U8 -> 9479.8706 | W8: =+R8-V8 -> 22390.329 | X8: =+V8/$R$8 -> 0.2974525 | Y8: =+W8/$R$8 -> 0.7025475
C9: Obra USD CIF | D9: 451303 | E9: =+D9*$F$6 -> 9026.06 | H9: 0 | I9: =+D9-H9 -> 451303 | J9: =+E9/I9 -> 0.02 | M9: Obra USD CIF | N9: 451303 | O9: =+N9*$F$6 -> 9026.06 | P9: 6769.545 | Q9: 6769.545 | R9: =+O9+P9+Q9 -> 22565.15 | S9: =+'Básico USD CIF'!I9 -> 2095.7028 | T9: =+'Básico USD CIF'!J9 -> 1571.7771 | U9: =+'Básico USD CIF'!K9 -> 1571.7771 | V9: =+S9+T9+U9 -> 5239.257 | W9: =+R9-V9 -> 17325.893 | X9: =+V9/$R$9 -> 0.23218357 | Y9: =+W9/$R$9 -> 0.76781643
B11: Concepto | D11: Montos contratados | E11: Acopio pago | F11: 0.015 | G11: Fecha pago | H11: Acumulado a la fecha | I11: Saldo a la fecha | J11: Nuevo % desacopio | K11: OP GP
B12: Acopio 2 (1,5%) | C12: Obra pesos | D12: 446784590 | E12: =+D12*$F$11 -> 6701768.8 | G12: 45975 | H12: =+'Básico $'!F4+'Básico $'!F5+'Básico $'!F6+'Básico $'!F7+'Básico $'!F8+'Básico $'!F9+'Básico $'!F10+'Básico $'!F11+'Básico $'!F12+'Básico $'!F13+'Básico $'!F14 -> 1.4658636e+08 | I12: =+D12-H12 -> 3.0019823e+08 | J12: 0.022324 | K12: 074
C13: Obra USD | D13: 637404 | E13: =+D13*$F$11 -> 9561.06 | H13: 0 | I13: =+D13-H13 -> 637404 | J13: =+E13/I13 -> 0.015
C14: Obra USD CIF | D14: 451303 | E14: =+D14*$F$11 -> 6769.545 | H14: 0 | I14: =+D14-H14 -> 451303 | J14: =+E14/I14 -> 0.015
B16: Concepto | D16: Montos contratados | E16: Acopio pago | F16: 0.015 | G16: Fecha pago | H16: Acumulado a la fecha | I16: Saldo a la fecha | J16: Nuevo % desacopio | K16: OP GP
B17: Acopio 3 (1,5%) | C17: Obra pesos | D17: 446784590 | E17: =+D17*$F$11 -> 6701768.8 | G17: 46101 | H17: 2.107935e+08 | I17: =+D17-H17 -> 2.3599109e+08 | J17: 0.028398 | K17: 102
C18: Obra USD | D18: 637404 | E18: =+D18*$F$11 -> 9561.06 | H18: =+'Básico USD Plaza'!F4 -> 17074.7 | I18: =+D18-H18 -> 620329.3 | J18: =+E18/I18 -> 0.015412878
C19: Obra USD CIF | D19: 451303 | E19: =+D19*$F$11 -> 6769.545 | H19: 0 | I19: =+D19-H19 -> 451303 | J19: =+E19/I19 -> 0.015
B53: ETAPA 2 - proyectado para flujo
B55: Pagos acopio y cálculo % desacopio | M55: tc | N55: 38.792
B57: Concepto | D57: Montos contratados | E57: Acopio a pagar | F57: 0.02 | G57: Fecha a pagar | H57: Acumulado a la fecha | I57: Saldo a la fecha | J57: Nuevo % desacopio | K57: OP GP
B58: Acopio 1 (2%) | C58: Obra pesos | D58: 166552456 | E58: =D58*$F$57 -> 3331049.1 | G58: sept-26 | H58: 30437309 | I58: =+D58+(D59*TC+D60*TC)-H58 -> 1.5625428e+08 | J58: =(E58+(E59*TC+E60*TC))/I58 -> 0.023895869
C59: Obra USD | D59: 294444.5 | E59: =D59*$F$57 -> 5888.89
C60: Obra USD CIF | D60: 224712.3 | E60: =D60*$F$57 -> 4494.246
B62: Concepto | D62: Montos contratados | E62: Acopio a pagar | F62: 0.015 | G62: Fecha a pagar | H62: Acumulado a la fecha | I62: Saldo a la fecha | J62: Nuevo % desacopio | K62: OP GP
B63: Acopio 2 (1,5%) | C63: Obra pesos | D63: 166552456 | E63: =+D63*$F$62 -> 2498286.8 | G63: 46357 | H63: 69480418 | I63: =+D63+(D64*TC+D65*TC)-H63 -> 1.1721117e+08 | J63: =(E63+(E64*TC+E65*TC))/I63 -> 0.023891698
C64: Obra USD | D64: 294444.5 | E64: =+D64*$F$62 -> 4416.6675
C65: Obra USD CIF | D65: 224712.3 | E65: =+D65*$F$62 -> 3370.6845
B67: Concepto | D67: Montos contratados | E67: Acopio a pagar | F67: 0.015 | G67: Fecha a pagar | H67: Acumulado a la fecha | I67: Saldo a la fecha | J67: Nuevo % desacopio | K67: OP GP
B68: Acopio 3 (1,5%) | C68: Obra pesos | D68: 166552456 | E68: =+D68*$F$67 -> 2498286.8 | G68: 46508 | H68: 133306761 | I68: =+D68+(D69*TC+D70*TC)-H68 -> 53384826 | J68: =(E68+(E69*TC+E70*TC))/I68 -> 0.052456363
C69: Obra USD | D69: 294444.5 | E69: =+D69*$F$67 -> 4416.6675
C70: Obra USD CIF | D70: 224712.3 | E70: =+D70*$F$67 -> 3370.6845
D74: Acop 1 total pesos | E74: =+E58+E59*TC+E60*TC -> 3733831.7
D75: Acop 2 total pesos | E75: =+E63+E64*TC+E65*TC -> 2800373.8
D76: Acop 3 total pesos | E76: =+E68+E70*TC+E69*TC -> 2800373.8

Sheet Básico $
B1: Monto contratado | C1: 446784590
AB2: Avance básico | AG2: IVA | AM2: Acopio | AR2: Garantía | AX2: Canje
B3: N° Certificado | C3: Mes certificado | D3: Factura | E3: Fecha factura | F3: Subtotal | G3: IVA | H3: Total | I3: Acopio 1 | J3: Acopio 2 | K3: Acopio 3 | L3: Garantía (Retención fondo reparo) | M3: Canje unidades (Retención complementaria) | N3: Subtotal a pagar | O3: Aportes patronales por partidas exentas | P3: Monto a pagar | Q3: Pago | R3: Saldo | S3: Fecha pago | T3: Comentario | U3: Carta IVA | V3: OP GP | X3: Resumen | AB3: Monto contratado | AC3: =+C1 -> 446784590 | AG3: IVA contrato | AH3: =+AC3*0.22 -> 98292610 | AM3: Acopio | AN3: =+AC3*0.05 -> 22339230 | AR3: Garantía | AS3: =+AC3*0.05 -> 22339230 | AX3: Canje | AY3: =+AC3*0.025 -> 11169615
B4: 1 (adelanto) | C4: 45627 | D4: A-4657 | E4: 45688 | F4: 3020726 | G4: =+F4*0.22 -> 664559.72 | H4: =+F4+G4 -> 3685285.7 | L4: =+F4*0.05 -> 151036.3 | M4: =+F4*0.025 -> 75518.15 | N4: =+F4-I4-J4-K4-L4-M4 -> 2794171.6 | P4: =+F4-I4-J4-K4-L4-M4 -> 2794171.6 | Q4: 2794172 | R4: =+P4-Q4 -> -0.45 | S4: 45646 | T4: primero se hizo factura A-4589 y se anulo mediante NC 1728 | U4: 1 | V4: 036 | X4: =+AB4 -> Monto avanzado | Y4: =+AC4 -> 2.6810641e+08 | AB4: Monto avanzado | AC4: =+F25 -> 2.6810641e+08 | AG4: IVA avanzado | AH4: =+G25 -> 58983410 | AM4: Acopio utilzado | AN4: =+I25+J25+K25 -> 8636156.9 | AR4: Garantía retenida | AS4: =+L25 -> 13405321 | AX4: Canje utilizado | AY4: =+M25 -> 6702660.3
B5: 2 (adelanto) | C5: 45658 | D5: A-4658 | E5: 45688 | F5: 2620526 | G5: =+F5*0.22 -> 576515.72 | H5: =+F5+G5 -> 3197041.7 | L5: =+F5*0.05 -> 131026.3 | M5: =+F5*0.025 -> 65513.15 | N5: =+F5-I5-J5-K5-L5-M5 -> 2423986.6 | P5: =+F5-I5-J5-K5-L5-M5 -> 2423986.6 | Q5: 2423986.2 | R5: =+P5-Q5 -> 0.33 | S5: 45714 | U5: 1 | V5: 038 | X5: =+AG3 -> IVA contrato | Y5: =+AH3 -> 98292610 | AB5: Avance pendiente | AC5: =+AC3-AC4 -> 1.7867818e+08 | AG5: IVA pendiente | AH5: =+AH3-AH4 -> 39309200 | AM5: Acopio pendiente | AN5: =+AN3-AN4 -> 13703073 | AR5: Garantía pendiente | AS5: =+AS3-AS4 -> 8933909 | AX5: Canje pendiente | AY5: =+AY3-AY4 -> 4466954.5
B6: 3 (adelanto) | C6: 45689 | D6: A-4685 | E6: 45716 | F6: 7539478 | G6: =+F6*0.22 -> 1658685.2 | H6: =+F6+G6 -> 9198163.2 | L6: =+F6*0.05 -> 376973.9 | M6: =+F6*0.025 -> 188486.95 | N6: =+F6-I6-J6-K6-L6-M6 -> 6974017.1 | P6: =+F6-I6-J6-K6-L6-M6 -> 6974017.1 | Q6: 6974017.1 | R6: =+P6-Q6 -> 0 | S6: 45736 | U6: 2 | V6: 040 | X6: Monto avanzado con IVA | Y6: =+Y4+Y5 -> 3.6639902e+08
B7: 4 (adelanto) | C7: 45717 | D7: A-4714 | E7: 45747 | F7: 14122299 | G7: =+F7*0.22 -> 3106905.8 | H7: =+F7+G7 -> 17229205 | L7: =+F7*0.05 -> 706114.95 | M7: =+F7*0.025 -> 353057.48 | N7: =+F7-I7-J7-K7-L7-M7 -> 13063127 | P7: =+F7-I7-J7-K7-L7-M7 -> 13063127 | Q7: 13063127 | R7: =+P7-Q7 -> -0.004999999 | S7: 45757 | U7: 3 | V7: 042 | X7: =+AM4 -> Acopio utilzado | Y7: =+AN4 -> 8636156.9
B8: 5 (adelanto) | C8: 45748 | D8: A-4736 | E8: 45777 | F8: 7660122 | G8: =+F8*0.22 -> 1685226.8 | H8: =+F8+G8 -> 9345348.8 | L8: =+F8*0.05 -> 383006.1 | M8: =+F8*0.025 -> 191503.05 | N8: =+F8-I8-J8-K8-L8-M8 -> 7085612.9 | P8: =+F8-I8-J8-K8-L8-M8 -> 7085612.9 | Q8: 7085612.9 | R8: =+P8-Q8 -> 0 | S8: 45796 | U8: 4 | V8: 045 | X8: =+AR4 -> Garantía retenida | Y8: =+AS4 -> 13405321
B9: 6 | C9: 45778 | D9: A-4787 | E9: 45808 | F9: 13979077 | G9: =+F9*0.22 -> 3075396.9 | H9: =+F9+G9 -> 17054474 | I9: =+F9*2.1698% -> 303318.01 | L9: =+F9*0.05 -> 698953.85 | M9: =+F9*0.025 -> 349476.93 | N9: =+F9-I9-J9-K9-L9-M9 -> 12627328 | P9: =+F9-I9-J9-K9-L9-M9 -> 12627328 | Q9: 12627328 | R9: =+P9-Q9 -> 0.0022539981 | S9: 45835 | U9: 5 | V9: 056B | X9: =+AX4 -> Canje utilizado | Y9: =+AY4 -> 6702660.3
B10: 7 | C10: 45809 | D10: A-4808 (A-1776) | E10: 45838 | F10: 14933843 | G10: =+F10*0.22 -> 3285445.6 | H10: =+F10+G10 -> 18219289 | I10: =+F10*2.1698% -> 324034.54 | L10: =+F10*0.05 -> 746692.17 | M10: =+F10*0.025 -> 373346.09 | N10: =+F10-I10-J10-K10-L10-M10 -> 13489771 | O10: 11546 | P10: =+F10-I10-J10-K10-L10-M10-O10 -> 13478225 | Q10: 13478225 | R10: =+P10-Q10 -> -0.31682904 | S10: 45859 | U10: 6 | V10: 059 | X10: Aportes patronales | Y10: =+O25 -> 220082
B11: 8 | C11: 45839 | D11: A-4858 | E11: 45869 | F11: 15415139 | G11: =+F11*0.22 -> 3391330.6 | H11: =+F11+G11 -> 18806470 | I11: =+F11*2.1698% -> 334477.69 | L11: =+F11*0.05 -> 770756.95 | M11: =+F11*0.025 -> 385378.48 | N11: =+F11-I11-J11-K11-L11-M11 -> 13924526 | P11: =+F11-I11-J11-K11-L11-M11-O11 -> 13924526 | Q11: 13924526 | R11: =+P11-Q11 -> 0.0012421589 | S11: 45896 | U11: 7 | V11: 063 | X11: Pago | Y11: =+Y4-Y7-Y8-Y9-Y10 -> 2.3914219e+08
B12: 9 | C12: 45870 | D12: A-4914 (A-1790) | E12: 45900 | F12: 21666296 | G12: =+F12*0.22 -> 4766585.1 | H12: =+F12+G12 -> 26432881 | I12: =+F12*2.1698% -> 470115.29 | L12: =+F12*0.05 -> 1083314.8 | M12: =+F12*0.025 -> 541657.4 | N12: =+F12-I12-J12-K12-L12-M12 -> 19571209 | O12: 28774 | P12: =+F12-I12-J12-K12-L12-M12-O12 -> 19542435 | Q12: 19542435 | R12: =+P12-Q12 -> 0 | S12: 45919 | U12: 8 | V12: 067
B13: 10 | C13: 45901 | D13: A-4953 (A-1790) | E13: 45930 | F13: 20980633 | G13: =+F13*0.22 -> 4615739.3 | H13: =+F13+G13 -> 25596373 | I13: =+F13*2.1698% -> 455237.78 | L13: =+F13*0.05 -> 1049031.7 | M13: =+F13*0.025 -> 524515.83 | N13: =+F13-I13-J13-K13-L13-M13 -> 18951848 | O13: 14848 | P13: =+F13-I13-J13-K13-L13-M13-O13 -> 18937000 | Q13: 18937000 | R13: =+P13-Q13 -> 0.0043877438 | S13: 45952 | T13: ND 01 por aportes patronales | U13: 9 | V13: 071
B14: 11 | C14: 45931 | D14: A-4992 (A-1822) | E14: 45960 | F14: 24648219 | G14: =+F14*0.22 -> 5422608.2 | H14: =+F14+G14 -> 30070827 | I14: =+F14*2.1698% -> 534817.06 | J14: =+F14*2.063057% -> 508506.81 | L14: =+F14*0.05 -> 1232411 | M14: =+F14*0.025 -> 616205.48 | N14: =+F14-I14-J14-K14-L14-M14 -> 21756279 | O14: 18040 | P14: =+F14-I14-J14-K14-L14-M14-O14 -> 21738239 | Q14: 21738239 | R14: =+P14-Q14 -> 0.0029105991 | S14: 45982 | T14: ND 02 por aportes patronales | U14: 10 | V14: 076
B15: 11 | C15: 45931 | D15: A-4992 | E15: 45960 | J15: -508507 | N15: =+F15-I15-J15-K15-L15-M15 -> 508507 | P15: =+F15-I15-J15-K15-L15-M15-O15 -> 508507 | Q15: =+P15 -> 508507 | R15: =+P15-Q15 -> 0 | S15: 46010 | T15: Desacopio 2 no correspondía en certificado anterior | U15: 10 | V15: 082B
B16: 12 | C16: 45962 | D16: A-5064 (A-1829) | E16: 45991 | F16: 22369740 | G16: =+F16*0.22 -> 4921342.8 | H16: =+F16+G16 -> 27291083 | I16: =+F16*2.1698% -> 485378.62 | J16: =+F16*Acopios!$J$12 -> 499382.08 | L16: =+F16*0.05 -> 1118487 | M16: =+F16*0.025 -> 559243.5 | N16: =+F16-I16-J16-K16-L16-M16 -> 19707249 | O16: 22155 | P16: =+F16-I16-J16-K16-L16-M16-O16 -> 19685094 | Q16: =+P16 -> 19685094 | R16: =+P16-Q16 -> 0 | S16: 46010 | T16: ND 03 por aportes patronales | U16: 11 | V16: 082B
B17: 13 | C17: 45992 | D17: A-5108 (A-1859) | E17: 46008 | F17: 17503241 | G17: =+F17*0.22 -> 3850712.9 | H17: =+F17+G17 -> 21353954 | I17: =+F17*2.1698% -> 379785.32 | J17: =+F17*Acopios!$J$12 -> 390742.34 | L17: =+F17*0.05 -> 875162.03 | M17: =+F17*0.025 -> 437581.02 | N17: =+F17-I17-J17-K17-L17-M17 -> 15419970 | O17: 21051 | P17: =+F17-I17-J17-K17-L17-M17-O17 -> 15398919 | Q17: 15398919 | R17: =+P17-Q17 -> 0.0013556983 | S17: 46048 | T17: ND 04 por aportes patronales | U17: 12 | V17: 084
B18: 14 | C18: 46023 | D18: A-5191 (A-1881) | E18: 46053 | F18: 11909307 | G18: =+F18*0.22 -> 2620047.5 | H18: =+F18+G18 -> 14529355 | I18: =+F18*2.1698% -> 258408.14 | J18: =+F18*Acopios!$J$12 -> 265863.37 | L18: =+F18*0.05 -> 595465.35 | M18: =+F18*0.025 -> 297732.67 | N18: =+F18-I18-J18-K18-L18-M18 -> 10491837 | O18: 14772 | P18: =+F18-I18-J18-K18-L18-M18-O18 -> 10477065 | Q18: =+P18 -> 10477065 | R18: =+P18-Q18 -> 0 | S18: 46066 | T18: ND 05 por aportes patronales | U18: 13 | V18: 091
B19: 15 | C19: 46054 | D19: A-5235 (A-1899) | E19: 46081 | F19: 12424849 | G19: =+F19*0.22 -> 2733466.8 | H19: =+F19+G19 -> 15158316 | I19: =+F19*2.1698% -> 269594.37 | J19: =+F19*Acopios!$J$12 -> 277372.33 | L19: =+F19*0.05 -> 621242.45 | M19: =+F19*0.025 -> 310621.23 | N19: =+F19-I19-J19-K19-L19-M19 -> 10946019 | O19: 14060 | P19: =+F19-I19-J19-K19-L19-M19-O19 -> 10931959 | Q19: =+P19 -> 10931959 | R19: =+P19-Q19 -> 0 | S19: 46101 | T19: ND 06 por aportes patronales | U19: 14 | V19: 094
B20: 16 | C20: 46082 | D20: A-5342 | E20: 46112 | F20: 14998517 | G20: =+F20*0.22 -> 3299673.6 | H20: =+F20+G20 -> 18298190 | I20: =+F20*2.1698% -> 325437.81 | J20: =+F20*Acopios!$J$12 -> 334826.88 | K20: =+F20*Acopios!J17 -> 425927.87 | L20: =+F20*0.05 -> 749925.83 | M20: =+F20*0.025 -> 374962.91 | N20: =+F20-I20-J20-K20-L20-M20 -> 12787435 | O20: 17553 | P20: =+F20-I20-J20-K20-L20-M20-O20 -> 12769882 | Q20: 12769882 | R20: =+P20-Q20 -> -0.0027493984 | S20: 46147 | T20: ND 07 por aportes patronales | U20: 15 | V20: 105
B21: 17 | C21: 46113 | D21: A-5383 | E21: 46142 | F21: 12295338 | G21: =+F21*0.22 -> 2704974.4 | H21: =+F21+G21 -> 15000313 | I21: =+F21*2.1698% -> 266784.25 | J21: =+F21*Acopios!$J$12 -> 274481.13 | K21: =+F21*Acopios!$J$17 -> 349163.02 | L21: =+F21*0.05 -> 614766.91 | M21: =+F21*0.025 -> 307383.46 | N21: =+F21-I21-J21-K21-L21-M21 -> 10482759 | O21: 19349 | P21: =+F21-I21-J21-K21-L21-M21-O21 -> 10463410 | Q21: 10463410 | R21: =+P21-Q21 -> 0.0037107989 | S21: 46163 | T21: ND 010 por aportes patronales | U21: 16 | V21: 110
B22: 18 | C22: 46143 | D22: A-5478 | E22: 46173 | F22: 14976847 | G22: =+F22*0.22 -> 3294906.2 | H22: =+F22+G22 -> 18271753 | I22: =+F22*2.1698% -> 324967.62 | J22: =+F22*Acopios!$J$12 -> 334343.12 | K22: =+F22*Acopios!$J$17 -> 425312.49 | L22: =+F22*0.05 -> 748842.33 | M22: =+F22*0.025 -> 374421.16 | N22: =+F22-I22-J22-K22-L22-M22 -> 12768960 | O22: 17952 | P22: =+F22-I22-J22-K22-L22-M22-O22 -> 12751008 | Q22: =+P22 -> 12751008 | R22: =+P22-Q22 -> 0 | S22: 46198 | T22: ND 012 por aportes patronales | U22: 17 | V22: 116
B23: 19 | C23: 46174 | D23: A-5545 (A-1964) | E23: 46203 | F23: 15042213 | G23: =+F23*0.22 -> 3309286.9 | H23: =+F23+G23 -> 18351500 | I23: =+F23*2.1698% -> 326385.94 | J23: =+F23*Acopios!$J$12 -> 335802.36 | K23: =+F23*Acopios!$J$17 -> 427168.76 | L23: =+F23*0.05 -> 752110.65 | M23: =+F23*0.025 -> 376055.33 | N23: =+F23-I23-J23-K23-L23-M23 -> 12824690 | O23: 19982 | P23: =+F23-I23-J23-K23-L23-M23-O23 -> 12804708 | Q23: =+P23 -> 12804708 | R23: =+P23-Q23 -> 0 | S23: 46225 | T23: ND 015 por aportes patronales | U23: 18 | V23: 123
F25: =SUM(F4:F23) -> 2.6810641e+08 | G25: =SUM(G4:G23) -> 58983410 | H25: =SUM(H4:H23) -> 3.2708982e+08 | I25: =SUM(I4:I23) -> 5058742.4 | J25: =SUM(J4:J22) -> 2377011.1 | K25: =SUM(K4:K22) -> 1200403.4 | L25: =SUM(L4:L23) -> 13405321 | M25: =SUM(M4:M23) -> 6702660.3 | N25: =SUM(N4:N23) -> 2.385993e+08 | O25: =SUM(O4:O23) -> 220082 | P25: =SUM(P4:P23) -> 2.3837922e+08 | Q25: =SUM(Q4:Q22) -> 2.2557451e+08
M89: 58001
M90: 375823
M91: 1525603
M92: =SUM(M89:M91) -> 1959427

Sheet Básico USD Plaza
B1: Monto contratado | C1: 637404
Z2: Avance básico | AE2: IVA | AK2: Acopio | AP2: Garantía | AV2: Canje
B3: N° Certificado | C3: Fecha | D3: Factura | E3: Fecha factura | F3: Subtotal | G3: IVA | H3: Total | I3: Acopio 1 | J3: Acopio 2 | K3: Acopio 3 | L3: Garantía (Retención fondo reparo) | M3: Canje unidades (Retención complementaria) | N3: Monto a pagar | O3: Pago | P3: Saldo | Q3: Fecha pago | R3: Carta IVA | S3: OP GP | V3: Resumen | Z3: Monto contratado | AA3: =+C1 -> 637404 | AE3: IVA contrato | AF3: =+AA3*0.22 -> 140228.88 | AK3: Acopio | AL3: =+AA3*0.05 -> 31870.2 | AP3: Garantía | AQ3: =+AA3*0.05 -> 31870.2 | AV3: Canje | AW3: =+AA3*0.025 -> 15935.1
B4: 1 | C4: 46054 | D4: A-5245 | E4: 46081 | F4: 17074.7 | G4: =+F4*0.22 -> 3756.434 | H4: =+F4+G4 -> 20831.134 | I4: =+F4*Acopios!J8 -> 341.494 | J4: =+F4*Acopios!J13 -> 256.1205 | L4: =+F4*0.05 -> 853.735 | M4: =+F4*0.025 -> 426.8675 | N4: =+F4-I4-J4-K4-L4-M4 -> 15196.483 | O4: =+N4 -> 15196.483 | P4: =+N4-O4 -> 0 | Q4: 46101 | R4: 14 | S4: 095 | V4: =+Z4 -> Monto avanzado | W4: =+AA4 -> 193264.92 | Z4: Monto avanzado | AA4: =+F10 -> 193264.92 | AE4: IVA avanzado | AF4: =+G10 -> 42518.282 | AK4: Acopio utilzado | AL4: =+I10+J10+K10 -> 9479.8706 | AP4: Garantía retenida | AQ4: =+L10 -> 9663.246 | AV4: Canje utilizado | AW4: =+M10 -> 4831.623
B5: 2 | C5: 46082 | D5: A-5343 | E5: 46112 | F5: 20074.24 | G5: =+F5*0.22 -> 4416.3328 | H5: =+F5+G5 -> 24490.573 | I5: =+F5*Acopios!J8 -> 401.4848 | J5: =+F5*Acopios!J13 -> 301.1136 | K5: =+F5*Acopios!J18 -> 309.40182 | L5: =+F5*0.05 -> 1003.712 | M5: =+F5*0.025 -> 501.856 | N5: =+F5-I5-J5-K5-L5-M5 -> 17556.672 | O5: =+N5 -> 17556.672 | P5: =+N5-O5 -> 0 | Q5: 46141 | R5: 15 | S5: 106 | V5: =+AE3 -> IVA contrato | W5: =+AF3 -> 140228.88 | Z5: Avance pendiente | AA5: =+AA3-AA4 -> 444139.08 | AE5: IVA pendiente | AF5: =+AF3-AF4 -> 97710.598 | AK5: Acopio pendiente | AL5: =+AL3-AL4 -> 22390.329 | AP5: Garantía pendiente | AQ5: =+AQ3-AQ4 -> 22206.954 | AV5: Canje pendiente | AW5: =+AW3-AW4 -> 11103.477
B6: 3 | C6: 46113 | D6: A-5385 | E6: 46142 | F6: 36286.38 | G6: =+F6*0.22 -> 7983.0036 | H6: =+F6+G6 -> 44269.384 | I6: =+F6*Acopios!$J$8 -> 725.7276 | J6: =+F6*Acopios!$J$13 -> 544.2957 | K6: =+F6*Acopios!$J$18 -> 559.27756 | L6: =+F6*0.05 -> 1814.319 | M6: =+F6*0.025 -> 907.1595 | N6: =+F6-I6-J6-K6-L6-M6 -> 31735.601 | O6: 31735.6 | P6: =+N6-O6 -> 0.00064151163 | Q6: 46163 | R6: 16 | S6: 111 | V6: Monto avanzado con IVA | W6: =+W4+W5 -> 333493.8
B7: 4 | C7: 46143 | D7: A-5479 | E7: 46173 | F7: 38012.63 | G7: =+F7*0.22 -> 8362.7786 | H7: =+F7+G7 -> 46375.409 | I7: =+F7*Acopios!$J$8 -> 760.2526 | J7: =+F7*Acopios!$J$13 -> 570.18945 | K7: =+F7*Acopios!$J$18 -> 585.88404 | L7: =+F7*0.05 -> 1900.6315 | M7: =+F7*0.025 -> 950.31575 | N7: =+F7-I7-J7-K7-L7-M7 -> 33245.357 | O7: =+N7 -> 33245.357 | P7: =+N7-O7 -> 0 | Q7: 46198 | R7: 17 | S7: 117 | V7: =+AK4 -> Acopio utilzado | W7: =+AL4 -> 9479.8706
B8: 5 | C8: 46174 | D8: A-5529 | E8: 46203 | F8: 81816.97 | G8: =+F8*0.22 -> 17999.733 | H8: =+F8+G8 -> 99816.703 | I8: =+F8*Acopios!$J$8 -> 1636.3394 | J8: =+F8*Acopios!$J$13 -> 1227.2545 | K8: =+F8*Acopios!$J$18 -> 1261.035 | L8: =+F8*0.05 -> 4090.8485 | M8: =+F8*0.025 -> 2045.4243 | N8: =+F8-I8-J8-K8-L8-M8 -> 71556.068 | O8: 71556.07 | P8: =+N8-O8 -> -0.0017005847 | Q8: 46233 | R8: 18 | S8: 124 | V8: =+AP4 -> Garantía retenida | W8: =+AQ4 -> 9663.246
V9: =+AV4 -> Canje utilizado | W9: =+AW4 -> 4831.623
F10: =+SUM(F4:F8) -> 193264.92 | G10: =+SUM(G4:G8) -> 42518.282 | H10: =+SUM(H4:H8) -> 235783.2 | I10: =+SUM(I4:I8) -> 3865.2984 | J10: =+SUM(J4:J8) -> 2898.9738 | K10: =+SUM(K4:K8) -> 2715.5984 | L10: =+SUM(L4:L8) -> 9663.246 | M10: =+SUM(M4:M8) -> 4831.623 | ... O10: =+SUM(O4:O8) -> 169290.18 | V10: Pago | W10: =+W4-W7-W8-W9 -> 169290.18

Sheet Básico USD CIF
B1: Monto contratado | C1: 451303
Z2: Avance básico | AE2: Acopio | AJ2: Garantía | AO2: Canje
B3: N° Certificado | C3: Fecha | D3: Factura | E3: Fecha factura | F3: Subtotal | G3: IVA | H3: Total | I3: Acopio 1 | J3: Acopio 2 | K3: Acopio 3 | L3: Garantía (Retención fondo reparo) | M3: Canje unidades (Retención complementaria) | N3: Monto a pagar | O3: Pago | P3: Saldo | Q3: Fecha pago | R3: OP GP | S3: Comentario | V3: Resumen | Z3: Monto contratado | AA3: =+C1 -> 451303 | AE3: Acopio | AF3: =+AA3*0.05 -> 22565.15 | AJ3: Garantía | AK3: =+AA3*0.05 -> 22565.15 | AO3: Canje | AP3: =+AA3*0.025 -> 11282.575
B4: 1 | C4: 46082 | D4: A-5344 | E4: 46112 | F4: 89320 | G4: 0 | H4: =+F4 -> 89320 | I4: =+F4*Acopios!J9 -> 1786.4 | J4: =+F4*Acopios!J13 -> 1339.8 | K4: =+F4*Acopios!J19 -> 1339.8 | L4: =+F4*0.05 -> 4466 | M4: =+F4*0.025 -> 2233 | N4: =+F4-I4-J4-K4-L4-M4 -> 78155 | O4: =+N4 -> 78155 | P4: =+N4-O4 -> 0 | Q4: 46141 | R4: 107 | V4: =+Z4 -> Monto avanzado | W4: =+AA4 -> 104785.14 | Z4: Monto avanzado | AA4: =+F9 -> 104785.14 | AE4: Acopio utilzado | AF4: =+I9+J9+K9 -> 5239.257 | AJ4: Garantía retenida | AK4: =+L9 -> 5239.257 | AO4: Canje utilizado | AP4: =+M9 -> 2619.6285
B5: 2 | C5: 46113 | D5: A-5388 | E5: 46142 | F5: 2157.01 | G5: 0 | H5: =+F5 -> 2157.01 | I5: =+F5*Acopios!$J$9 -> 43.1402 | J5: =+F5*Acopios!$J$13 -> 32.35515 | K5: =+F5*Acopios!$J$19 -> 32.35515 | L5: =+F5*0.05 -> 107.8505 | M5: =+F5*0.025 -> 53.92525 | N5: =+F5-I5-J5-K5-L5-M5 -> 1887.3838 | O5: 1887 | P5: =+N5-O5 -> 0.38375 | Q5: 46163 | R5: 112 | V5: =+AE4 -> Acopio utilzado | W5: =+AF4 -> 5239.257 | Z5: Avance pendiente | AA5: =+AA3-AA4 -> 346517.86 | AE5: Acopio pendiente | AF5: =+AF3-AF4 -> 17325.893 | AJ5: Garantía pendiente | AK5: =+AK3-AK4 -> 17325.893 | AO5: Canje pendiente | AP5: =+AP3-AP4 -> 8662.9465
B6: 3 | C6: 46143 | D6: A-5481 | E6: 46173 | F6: 10376.53 | G6: 0 | H6: =+F6 -> 10376.53 | I6: =+F6*Acopios!$J$9 -> 207.5306 | J6: =+F6*Acopios!$J$13 -> 155.64795 | K6: =+F6*Acopios!$J$19 -> 155.64795 | L6: =+F6*0.05 -> 518.8265 | M6: =+F6*0.025 -> 259.41325 | N6: =+F6-I6-J6-K6-L6-M6 -> 9079.4638 | O6: =+N6 -> 9079.4638 | P6: =+N6-O6 -> 0 | Q6: 46198 | R6: 118 | V6: =+AJ4 -> Garantía retenida | W6: =+AK4 -> 5239.257
B7: 4 | C7: 46174 | D7: A-5531 | E7: 46203 | F7: 2931.6 | G7: 0 | H7: =+F7 -> 2931.6 | I7: =+F7*Acopios!$J$9 -> 58.632 | J7: =+F7*Acopios!$J$13 -> 43.974 | K7: =+F7*Acopios!$J$19 -> 43.974 | L7: =+F7*0.05 -> 146.58 | M7: =+F7*0.025 -> 73.29 | N7: =+F7-I7-J7-K7-L7-M7 -> 2565.15 | O7: 2565.15 | P7: =+N7-O7 -> 0 | Q7: 46233 | R7: 125 | V7: =+AO4 -> Canje utilizado | W7: =+AP4 -> 2619.6285
V8: Pago | W8: =+W4-W5-W6-W7 -> 91686.997
F9: =+SUM(F4:F7) -> 104785.14 | G9: =+SUM(G4:G7) -> 0 | H9: =+SUM(H4:H7) -> 104785.14 | I9: =+SUM(I4:I7) -> 2095.7028 | J9: =+SUM(J4:J7) -> 1571.7771 | K9: =+SUM(K4:K7) -> 1571.7771 | L9: =+SUM(L4:L7) -> 5239.257 | M9: =+SUM(M4:M7) -> 2619.6285 | ... O9: =+SUM(O4:O7) -> 91686.614

Sheet AyD $
B2: OC | C2: Fecha | D2: Factura | E2: Fecha factura | F2: Presupuesto | I2: Avance | N2: Pago | O2: Saldo | P2: Fecha pago | Q2: Carta IVA | R2: OP GP | U2: Resumen | AA2: Subtotal por OC | AH2: Subtotal por mes
F3: Subtotal | G3: IVA | H3: Total | I3: Porcentaje | J3: Subtotal | K3: Retención de garantía | L3: Monto a pagar | U3: Monto avanzado | V3: =+F11 -> 557349.38 | AA3: Mes | AB3: OC 2 | AC3: OC 3 | AD3: OC 4 | AE3: OC 6 | AF3: OC 13 | AH3: Mes | AI3: Subtotal
B4: 2 | C4: 45809 | D4: A-4823 | E4: 45838 | F4: 138254.19 | G4: =+F4*0.22 -> 30415.922 | H4: =+F4+G4 -> 168670.11 | I4: 0.66666667 | J4: =+F4*I4 -> 92169.46 | K4: =+F4*I4*0.05 -> 4608.473 | L4: =+F4*I4-K4 -> 87560.987 | M4: =+L4+L5 -> 560177.06 | N4: 87561.5 | O4: =L4-N4 -> -0.51318042 | P4: 45869 | Q4: 6 | R4: 061 | U4: IVA certificados | V4: =+G11 -> 122616.86 | AA4: Jun-25 | AB4: =$J$4 -> 92169.46 | AC4: =$J$5 -> 497490.6 | AH4: Jun-25 | AI4: =+AB4+AC4 -> 589660.06
B5: 3 | D5: A-4824 | E5: 45838 | F5: 497490.6 | G5: =+F5*0.22 -> 109447.93 | H5: =+F5+G5 -> 606938.53 | I5: 1 | J5: =+F5*I5 -> 497490.6 | K5: =+F5*I5*0.05 -> 24874.53 | L5: =+F5*I5-K5 -> 472616.07 | N5: 472616.07 | O5: =L5-N5 -> 0.00021211331 | P5: 45869 | Q5: 6 | U5: Total IVA inc | V5: =+H11 -> 679966.24 | AA5: Jul-25 | AD5: =$J$6 -> 309912 | AH5: Jul-25 | AI5: =+AD5 -> 309912
B6: 4 | C6: 45839 | D6: A-4869 | E6: 45869 | F6: 309912 | G6: =+F6*0.22 -> 68180.64 | H6: =+F6+G6 -> 378092.64 | I6: 1 | J6: =+F6*I6 -> 309912 | K6: =+F6*I6*0.05 -> 15495.6 | L6: =+F6*I6-K6 -> 294416.4 | M6: =+L6 -> 294416.4 | N6: 294416.4 | O6: =L6-N6 -> 0 | P6: 45891 | Q6: 7 | R6: 064 | U6: Garantía retenida | V6: =+K11 -> 22772.803 | AA6: May-26 | AE6: =$J$7 -> -552655 | AF6: =$J$8 -> 108539 | AH6: May-26 | AI6: =+AE6+AF6 -> -444116
B7: 6 | C7: 46143 | D7: NC A-1950 | E7: 46173 | F7: -552655 | G7: =+F7*0.22 -> -121584.1 | H7: =+F7+G7 -> -674239.1 | I7: 1 | J7: =+F7*I7 -> -552655 | K7: =+F7*I7*0.05 -> -27632.75 | L7: =+F7*I7-K7 -> -525022.25 | M7: =+L7+L8 -> -421910.2 | N7: =+M7 -> -421910.2 | O7: =+M7-N7 -> 0 | P7: 46198 | Q7: 17 | R7: ND 013 | U7: Pago | V7: =+N11 -> 432683.77
B8: 13 | D8: A-5483 | E8: 46173 | F8: 164347.59 | G8: =+F8*0.22 -> 36156.47 | H8: =+F8+G8 -> 200504.06 | I8: 0.66042344 | J8: =+F8*I8 -> 108539 | K8: =+F8*I8*0.05 -> 5426.95 | L8: =+F8*I8-K8 -> 103112.05 | Q8: 17
F11: =SUM(F4:F9) -> 557349.38 | G11: =SUM(G4:G9) -> 122616.86 | H11: =SUM(H4:H9) -> 679966.24 | J11: =SUM(J4:J9) -> 455456.06 | K11: =SUM(K4:K9) -> 22772.803 | L11: =SUM(L4:L9) -> 432683.26 | N11: =SUM(N4:N9) -> 432683.77

Sheet AYD USD Plaza 
B2: OC | C2: Fecha | D2: Factura | E2: Presupuesto | H2: Avance | M2: Pago | N2: Saldo | O2: Fecha pago | P2: Carta IVA | Q2: OP GP | R2: Comentario
E3: Subtotal | F3: IVA | G3: Total | H3: Porcentaje | I3: Subtotal | J3: Garantía | K3: Monto a pagar | U3: Resumen | Y3: Subtotal por rubro | AC3: Subtotal por mes
B4: 5 | C4: 46082 | D4: A-5345 | E4: 111468 | F4: =+E4*0.22 -> 24522.96 | G4: =+E4+F4 -> 135990.96 | H4: 0.7963251 | I4: =+E4*H4 -> 88764.766 | J4: =I4*0.05 -> 4438.2383 | K4: =+E4*H4-J4 -> 84326.528 | L4: =+K4+K5 -> 84853.967 | M4: =+K4+K5 -> 84853.967 | N4: =+K4+K5-M4 -> 0 | O4: 46141 | P4: 15 | Q4: 108 | R4: Avance ascensores marzo 2026, pasa de CIF a plaza | U4: Monto avanzado | V4: =+E13 -> 472645.24 | Y4: Mes | Z4: Ascensores | AA4: Admin subcontratos | AC4: Mes | AD4: Subtotal
E5: 6693.3097 | F5: =+E5*0.22 -> 1472.5281 | G5: =+E5+F5 -> 8165.8378 | H5: 0.082948362 | I5: =+E5*H5 -> 555.19907 | J5: =I5*0.05 -> 27.759954 | K5: =+E5*H5-J5 -> 527.43912 | Q5: 109 | R5: Avance sub contratos marzo 2026, pasa de CIF a plaza | U5: IVA certificados | V5: =+F13 -> 103981.95 | Y5: Jun-25 | Z5: =+I4 -> 88764.766 | AA5: =+I5 -> 555.19907 | AC5: Jun-25 | AD5: =+Z5+AA5 -> 89319.965
B6: 5 | C6: 46113 | D6: A-5386 | E6: 111468 | F6: =+E6*0.22 -> 24522.96 | G6: =+E6+F6 -> 135990.96 | H6: 0.01265625 | I6: =+E6*H6 -> 1410.7669 | J6: =I6*0.05 -> 70.538344 | K6: =+E6*H6-J6 -> 1340.2285 | L6: =+K6+K7 -> 2049.2174 | M6: =+K6+K7 -> 2049.2174 | N6: =+K6+K7-M6 -> 0 | O6: 46163 | P6: 16 | Q6: 113 | R6: Avance ascensores y subcontratos abril 2026, pasa de CIF a plaza | U6: Total IVA inc | V6: =+G13 -> 576627.19 | Y6: Jul-25 | Z6: =+I6 -> 1410.7669 | AA6: =+I7 -> 746.30403 | AC6: Jul-25 | AD6: =+Z6+AA6 -> 2157.0709
E7: 6693.3097 | F7: =+E7*0.22 -> 1472.5281 | G7: =+E7+F7 -> 8165.8378 | H7: 0.1115 | I7: =+E7*H7 -> 746.30403 | J7: =I7*0.05 -> 37.315201 | K7: =+E7*H7-J7 -> 708.98883 | U7: Garantía retenida | V7: =+J13 -> 5200.5318 | Y7: May-26 | Z7: =+I8 -> 9753.45 | AA7: =+I9 -> 623.07854 | AC7: May-26 | AD7: =+Z7+AA7 -> 10376.529
B8: 5 | C8: 46143 | D8: A-5480 | E8: 111468 | F8: =+E8*0.22 -> 24522.96 | G8: =+E8+F8 -> 135990.96 | H8: 0.0875 | I8: =+E8*H8 -> 9753.45 | J8: =I8*0.05 -> 487.6725 | K8: =+E8*H8-J8 -> 9265.7775 | L8: =+K8+K9 -> 9857.7021 | M8: =+L8 -> 9857.7021 | N8: =+K8+K9-M8 -> 0 | O8: 46198 | P8: 17 | Q8: 119 | R8: Avance ascensores y subcontratos mayo 2026, pasa de CIF a plaza | U8: Pago | V8: =+M13 -> 98809.886
E9: 6693.3097 | F9: =+E9*0.22 -> 1472.5281 | G9: =+E9+F9 -> 8165.8378 | H9: 0.093089753 | I9: =+E9*H9 -> 623.07854 | J9: =I9*0.05 -> 31.153927 | K9: =+E9*H9-J9 -> 591.92461
B10: 5 | C10: 46174 | D10: A-5530 | E10: 111468 | F10: =+E10*0.22 -> 24522.96 | G10: =+E10+F10 -> 135990.96 | H10: 0.01265625 | I10: =+E10*H10 -> 1410.7669 | J10: =I10*0.05 -> 70.538344 | K10: =+E10*H10-J10 -> 1340.2285 | L10: 2049 | M10: 2049 | N10: =+K10+K11-M10 -> 0.21735647 | O10: 46233 | P10: 18 | Q10: 126 | R10: Avance ascensores y subcontratos junio 2026, pasa de CIF a plaza
E11: 6693.3097 | F11: =+E11*0.22 -> 1472.5281 | G11: =+E11+F11 -> 8165.8378 | H11: 0.1115 | I11: =+E11*H11 -> 746.30403 | J11: =I11*0.05 -> 37.315201 | K11: =+E11*H11-J11 -> 708.98883
E13: =SUM(E4:E11) -> 472645.24 | F13: =SUM(F4:F11) -> 103981.95 | G13: =SUM(G4:G11) -> 576627.19 | J13: =SUM(J4:J11) -> 5200.5318 | M13: =SUM(M4:M11) -> 98809.886

Sheet AYD USD CIF
B2: OC | C2: Fecha | D2: Factura | E2: Presupuesto | H2: Avance | M2: Pago | N2: Saldo | O2: Fecha pago | P2: OP GP | Q2: Comentarios
E3: Subtotal | F3: IVA | G3: Total | H3: Porcentaje | I3: Subtotal | J3: Garantía | K3: Monto a pagar | T3: Resumen | Y3: Subtotal por rubro | AC3: Subtotal por mes
B4: 5 | C4: 46082 | D4: A-1921 | E4: -111468 | F4: 0 | G4: =+E4+F4 -> -111468 | H4: 0.7963251 | I4: =+E4*H4 -> -88764.766 | J4: =+I4*0.05 -> -4438.2383 | K4: =+E4*H4-J4 -> -84326.528 | L4: =+K4+K5 -> -84853.967 | M4: =+K4+K5 -> -84853.967 | N4: =+K4+K5-M4 -> 0 | O4: 46141 | P4: ND 008B | Q4: Avance ascensores marzo 2026 pasa de CIF a Plaza | T4: Monto avanzado | U4: =+E13 -> -472645.24 | Y4: Mes | Z4: Ascensores | AA4: Admin subcontratos | AC4: Mes | AD4: Subtotal
E5: -6693.3097 | F5: 0 | G5: =+E5 -> -6693.3097 | H5: 0.082948362 | I5: =+E5*H5 -> -555.19907 | J5: =+I5*0.05 -> -27.759954 | K5: =+E5*H5-J5 -> -527.43912 | P5: ND 009 | Q5: Avance sub contratos marzo 2026, pasa de CIF a plaza | T5: IVA certificados | U5: =+F13 -> -25995.488 | Y5: Jun-25 | Z5: =+I4 -> -88764.766 | AA5: =+I5 -> -555.19907 | AC5: Jun-25 | AD5: =+Z5+AA5 -> -89319.965
B6: 5 | C6: 46113 | D6: A-1927 | E6: -111468 | F6: 0 | G6: =+E6+F6 -> -111468 | H6: 0.01265625 | I6: =+E6*H6 -> -1410.7669 | J6: =+I6*0.05 -> -70.538344 | K6: =+E6*H6-J6 -> -1340.2285 | L6: =+K6+K7 -> -2049.2174 | M6: =+K6+K7 -> -2049.2174 | N6: =+K6+K7-M6 -> 0 | O6: 46163 | P6: ND 011 | Q6: Avance ascensores y subcontratos abril 2026, pasa de CIF a plaza | T6: Total IVA inc | U6: =+G13 -> -498640.73 | Y6: Jul-25 | Z6: =+I6 -> -1410.7669 | AA6: =+I7 -> -746.30403 | AC6: Jul-25 | AD6: =+Z6+AA6 -> -2157.0709
E7: -6693.3097 | F7: 0 | G7: =+E7+F7 -> -6693.3097 | H7: 0.1115 | I7: =+E7*H7 -> -746.30403 | J7: =+I7*0.05 -> -37.315201 | K7: =+E7*H7-J7 -> -708.98883 | T7: Garantía retenida | U7: =+J13 -> -5200.5318 | Y7: May-26 | Z7: =+I8 -> -9753.45 | AA7: =+I9 -> -623.07854 | AC7: May-26 | AD7: =+Z7+AA7 -> -10376.529
B8: 5 | C8: 46143 | D8: A-1949 | E8: -111468 | F8: 0 | G8: =+E8+F8 -> -111468 | H8: 0.0875 | I8: =+E8*H8 -> -9753.45 | J8: =+I8*0.05 -> -487.6725 | K8: =+E8*H8-J8 -> -9265.7775 | L8: =+K8+K9 -> -9857.7021 | M8: =+L8 -> -9857.7021 | N8: =+K8+K9-M8 -> 0 | O8: 46198 | P8: ND 014 | Q8: Avance ascensores y subcontratos mayo 2026, pasa de CIF a plaza | T8: Pago | U8: =+M13 -> -98809.886
E9: -6693.3097 | F9: 0 | G9: =+E9+F9 -> -6693.3097 | H9: 0.093089753 | I9: =+E9*H9 -> -623.07854 | J9: =+I9*0.05 -> -31.153927 | K9: =+E9*H9-J9 -> -591.92461
B10: 5 | C10: 46174 | D10: A-1965 | E10: -111468 | F10: =+E10*0.22 -> -24522.96 | G10: =+E10+F10 -> -135990.96 | H10: 0.01265625 | I10: =+E10*H10 -> -1410.7669 | J10: =I10*0.05 -> -70.538344 | K10: =+E10*H10-J10 -> -1340.2285 | L10: =+K10+K11 -> -2049.2174 | M10: -2049 | N10: =+K10+K11-M10 -> -0.21735647 | O10: 46233 | P10: ND 017 | Q10: Avance ascensores y subcontratos junio 2026, pasa de CIF a plaza
E11: -6693.3097 | F11: =+E11*0.22 -> -1472.5281 | G11: =+E11+F11 -> -8165.8378 | H11: 0.1115 | I11: =+E11*H11 -> -746.30403 | J11: =I11*0.05 -> -37.315201 | K11: =+E11*H11-J11 -> -708.98883
E13: =SUM(E4:E11) -> -472645.24 | F13: =SUM(F4:F11) -> -25995.488 | G13: =SUM(G4:G11) -> -498640.73 | J13: =SUM(J4:J11) -> -5200.5318 | M13: =SUM(M4:M11) -> -98809.886

Sheet AP
B2: N° Certificado | C2: Mes certificado | D2: Factura | E2: Fecha factura | F2: Subtotal | G2: IVA | H2: Total | I2: Garantía (Retención fondo reparo) | J2: Canje unidades (Retención complementaria) | L2: Aportes patronales por partidas exentas | M2: Monto a pagar | N2: Pago | O2: Fecha pago | P2: Comentario | Q2: Carta IVA | R2: Monto certificado | S2: % Ajuste | T2: Variacion | U2: OP GP | Y2: Resumen | AL2: =+C2 -> Mes certificado | AM2: =+S2 -> % Ajuste
B3: 1 (adelanto) | C3: 45627 | D3: A-4769 (A1776) | E3: 45803 | F3: 60057.54 | G3: =+F3*0.22 -> 13212.659 | H3: =+F3+G3 -> 73270.199 | I3: =+F3*0.05 -> 3002.877 | J3: =+F3*0.025 -> 1501.4385 | K3: =+L3+M3 -> 55553.224 | L3: 1931 | M3: =+F3-I3-J3-L3 -> 53622.224 | N3: 53622.22 | O3: 45835 | Q3: 5 | R3: =+'Básico $'!F4 -> 3020726 | S3: =+F3/R3 -> 0.019881823 | U3: 051B | Y3: Monto avanzado | Z3: =+F24 -> 14041077 | AL3: =+C3 -> 45627 | AM3: =+S3 -> 0.019881823
B4: 2 (adelanto) | C4: 45658 | D4: A-4770 (A1776) | E4: 45803 | F4: 57599.76 | G4: =+F4*0.22 -> 12671.947 | H4: =+F4+G4 -> 70271.707 | I4: =+F4*0.05 -> 2879.988 | J4: =+F4*0.025 -> 1439.994 | K4: =+L4+M4 -> 53279.778 | L4: 821 | M4: =+F4-I4-J4-L4 -> 52458.778 | N4: 52458.78 | O4: 45835 | Q4: 5 | R4: =+'Básico $'!F5 -> 2620526 | S4: =+F4/R4 -> 0.021980228 | T4: =+S4-S3 -> 0.0020984053 | U4: 052B | Y4: IVA certificados | Z4: =+G24 -> 3089037 | AL4: =+C4 -> 45658 | AM4: =+S4 -> 0.021980228
B5: 3 (adelanto) | C5: 45689 | D5: A-4771 (A1776) | E5: 45803 | F5: 210401.13 | G5: =+F5*0.22 -> 46288.249 | H5: =+F5+G5 -> 256689.38 | I5: =+F5*0.05 -> 10520.057 | J5: =+F5*0.025 -> 5260.0283 | K5: =+L5+M5 -> 194621.05 | L5: 4689 | M5: =+F5-I5-J5-L5 -> 189932.05 | N5: 189932.05 | O5: 45835 | Q5: 5 | R5: =+'Básico $'!F6 -> 7539478 | S5: =+F5/R5 -> 0.027906591 | T5: =+S5-S4 -> 0.0059263627 | U5: 053B | Y5: Total IVA inc | Z5: =+H24 -> 17130115 | AL5: =+C5 -> 45689 | AM5: =+S5 -> 0.027906591
B6: 4 (adelanto) | C6: 45717 | D6: A-4772 (A1776) | E6: 45803 | F6: 395161.09 | G6: =+F6*0.22 -> 86935.44 | H6: =+F6+G6 -> 482096.53 | I6: =+F6*0.05 -> 19758.055 | J6: =+F6*0.025 -> 9879.0273 | K6: =+L6+M6 -> 365524.01 | L6: 8187 | M6: =+F6-I6-J6-L6 -> 357337.01 | N6: 357337.01 | O6: 45869 | Q6: 5 | R6: =+'Básico $'!F7 -> 14122299 | S6: =+F6/R6 -> 0.027981357 | T6: =+S6-S5 -> 7.4765855e-05 | U6: 054B | Y6: Garantía retenida | Z6: =+I24 -> 702053.87 | AL6: =+C6 -> 45717 | AM6: =+S6 -> 0.027981357
B7: 5 (adelanto) | C7: 45748 | D7: A-4804 (A1776) | E7: 45808 | F7: 445592.4 | G7: =+F7*0.22 -> 98030.328 | H7: =+F7+G7 -> 543622.73 | I7: =+F7*0.05 -> 22279.62 | J7: =+F7*0.025 -> 11139.81 | K7: =+L7+M7 -> 412172.97 | L7: 7976 | M7: =+F7-I7-J7-L7 -> 404196.97 | N7: 404196.97 | O7: 45869 | Q7: 5 | R7: =+'Básico $'!F8 -> 7660122 | S7: =+F7/R7 -> 0.058170405 | T7: =+S7-S6 -> 0.030189048 | U7: 055B | Y7: Canje unidades | Z7: =+J24 -> 351026.94 | AL7: =+C7 -> 45748 | AM7: =+S7 -> 0.058170405
B8: ajuste 4 y 5 | C8: Mar-25 y Abr-25 | D8: A-4848 | E8: 45860 | F8: 313.51 | G8: =+F8*0.22 -> 68.9722 | H8: =+F8+G8 -> 382.4822 | I8: =+F8*0.05 -> 15.6755 | J8: =+F8*0.025 -> 7.83775 | M8: =+F8-I8-J8-L8 -> 289.99675 | N8: 290 | O8: 45869 | Q8: 7 | U8: 054 + 055 | Y8: Aportes patronales | Z8: =+L24 -> 23604 | AL8: =+C9 -> 45778 | AM8: =+S9 -> 0.056973468
B9: 6 | C9: 45778 | D9: A-4842 | E9: 45838 | F9: 796436.49 | G9: =+F9*0.22 -> 175216.03 | H9: =+F9+G9 -> 971652.52 | I9: =+F9*0.05 -> 39821.825 | J9: =+F9*0.025 -> 19910.912 | M9: =+F9-I9-J9-L9 -> 736703.75 | N9: 736704 | O9: 45883 | Q9: 6 | R9: 13979077 | S9: =+F9/R9 -> 0.056973468 | T9: =+S9-S7 -> -0.0011969376 | U9: 063 | Y9: Pago | Z9: =+N24 -> 12964394 | AL9: =+C10 -> 45809 | AM9: =+S10 -> 0.056537865
B10: 7 | C10: 45809 | D10: A-4880 | E10: 45869 | F10: 844327.62 | G10: =+F10*0.22 -> 185752.08 | H10: =+F10+G10 -> 1030079.7 | I10: =+F10*0.05 -> 42216.381 | J10: =+F10*0.025 -> 21108.191 | M10: =+F10-I10-J10-L10 -> 781003.05 | N10: 781003.05 | O10: 45891 | Q10: 7 | R10: 14933843 | S10: =+F10/R10 -> 0.056537865 | T10: =+S10-S9 -> -0.000435603 | U10: 063 | AL10: =+C11 -> 45839 | AM10: =+S11 -> 0.054171145
B11: 8 | C11: 45839 | D11: A-4916 | E11: 45900 | F11: 835055.74 | G11: =+F11*0.22 -> 183712.26 | H11: =+F11+G11 -> 1018768 | I11: =+F11*0.05 -> 41752.787 | J11: =+F11*0.025 -> 20876.394 | M11: =+F11-I11-J11-L11 -> 772426.56 | N11: 772426.8 | O11: 45919 | Q11: 8 | R11: =+'Básico $'!F11 -> 15415139 | S11: =+F11/R11 -> 0.054171145 | T11: =+S11-S10 -> -0.0023667192 | U11: 067 | AL11: =+C12 -> 45870 | AM11: =+S12 -> 0.053394852
B12: 9 | C12: 45870 | D12: A-4954 | E12: 45930 | F12: 1156868.7 | G12: =+F12*0.22 -> 254511.11 | H12: =+F12+G12 -> 1411379.8 | I12: =+F12*0.05 -> 57843.433 | J12: =+F12*0.025 -> 28921.716 | M12: =+F12-I12-J12-L12 -> 1070103.5 | N12: 1070104.5 | O12: 45951 | Q12: 9 | R12: =+'Básico $'!F12 -> 21666296 | S12: =+F12/R12 -> 0.053394852 | T12: =+S12-S11 -> -0.00077629375 | U12: 071 | AL12: =+C13 -> 45901 | AM12: =+S13 -> 0.054137197
B13: 10 | C13: 45901 | D13: A-5017 | E13: 45960 | F13: 1135832.7 | G13: =+F13*0.22 -> 249883.19 | H13: =+F13+G13 -> 1385715.9 | I13: =+F13*0.05 -> 56791.635 | J13: =+F13*0.025 -> 28395.817 | M13: =+F13-I13-J13-L13 -> 1050645.2 | N13: 1050645.2 | O13: 45994 | Q13: 10 | R13: =+'Básico $'!F13 -> 20980633 | S13: =+F13/R13 -> 0.054137197 | T13: =+S13-S12 -> 0.00074234577 | U13: 076 | Y13: % Ajuste paramétrico actual | Z13: =+S21 -> 0.072382116 | AL13: =+C14 -> 45931 | AM13: =+S14 -> 0.058322639
B14: 11 | C14: 45931 | D14: A-5067 | E14: 45991 | F14: 1437549.2 | G14: =+F14*0.22 -> 316260.82 | H14: =+F14+G14 -> 1753810 | I14: =+F14*0.05 -> 71877.46 | J14: =+F14*0.025 -> 35938.73 | M14: =+F14-I14-J14-L14 -> 1329733 | N14: =+M14 -> 1329733 | O14: 46010 | Q14: 11 | R14: =+'Básico $'!F14 -> 24648219 | S14: =+F14/R14 -> 0.058322639 | T14: =+S14-S13 -> 0.0041854421 | U14: 082 | AL14: =+C15 -> 45962 | AM14: =+S15 -> 0.056718136
B15: 12 | C15: 45962 | D15: A-5144 | E15: 46022 | F15: 1268769.9 | G15: =+F15*0.22 -> 279129.39 | H15: =+F15+G15 -> 1547899.3 | I15: =+F15*0.05 -> 63438.497 | J15: =+F15*0.025 -> 31719.249 | M15: =+F15-I15-J15-L15 -> 1173612.2 | N15: =+M15 -> 1173612.2 | O15: 46045 | Q15: 12 | R15: =+'Básico $'!F16 -> 22369740 | S15: =+F15/R15 -> 0.056718136 | T15: =+S15-S14 -> -0.0016045037 | U15: 089 | AL15: 45992 | AM15: =+S16 -> 0.055338895
B16: 13 | C16: Dic-25 (provisorio) | D16: A-5141 | E16: 46022 | F16: 997262 | G16: =+F16*0.22 -> 219397.64 | H16: =+F16+G16 -> 1216659.6 | I16: =+F16*0.05 -> 49863.1 | J16: =+F16*0.025 -> 24931.55 | M16: =+F16-I16-J16-L16 -> 922467.35 | N16: =+M16 -> 922467.35 | O16: 46045 | Q16: 12 | R16: =+'Básico $'!F17 -> 17503241 | S16: =(+F16+F17)/R16 -> 0.055338895 | T16: =+S16-S15 -> -0.0013792405 | U16: 089 | AL16: =+C18 -> 46023 | AM16: =+S18 -> 0.058881092
B17: 14 | C17: Dic-25 (definitivo) | D17: NC1880 | E17: 46053 | F17: -28652 | G17: =+F17*0.22 -> -6303.44 | H17: =+F17+G17 -> -34955.44 | I17: =+F17*0.05 -> -1432.6 | J17: =+F17*0.025 -> -716.3 | M17: =+F17-I17-J17-L17 -> -26503.1 | N17: =+M17+M18 -> 622137.43 | O17: 46101 | P17: Se decuenta diferencia diciembre | Q17: 13 | U17: 091 | AL17: =+C19 -> 46054 | AM17: =+S19 -> 0.062799859
B18: 15 | C18: 46023 | D18: A-5236 | E18: 46081 | F18: 701233 | G18: =+F18*0.22 -> 154271.26 | H18: =+F18+G18 -> 855504.26 | I18: =+F18*0.05 -> 35061.65 | J18: =+F18*0.025 -> 17530.825 | M18: =+F18-I18-J18-L18 -> 648640.53 | Q18: 14 | R18: =+'Básico $'!F18 -> 11909307 | S18: =+F18/R18 -> 0.058881092 | T18: =+S18-S16 -> 0.0035421967 | U18: 094 | AL18: =+C20 -> 46082 | AM18: =+S20 -> 0.06628231
B19: 16 | C19: 46054 | D19: A-5341 | E19: 46112 | F19: 780278.76 | G19: =+F19*0.22 -> 171661.33 | H19: =+F19+G19 -> 951940.09 | I19: =+F19*0.05 -> 39013.938 | J19: =+F19*0.025 -> 19506.969 | M19: =+F19-I19-J19-L19 -> 721757.85 | N19: 721757.85 | O19: 46142 | Q19: 15 | R19: =+'Básico $'!F19 -> 12424849 | S19: =+F19/R19 -> 0.062799859 | T19: =+S19-S18 -> 0.0039187667 | U19: 107 | AL19: =+C21 -> 46113 | AM19: =+S21 -> 0.072382116
B20: 17 | C20: 46082 | D20: A-5384 | E20: 46142 | F20: 994136.32 | G20: =+F20*0.22 -> 218709.99 | H20: =+F20+G20 -> 1212846.3 | I20: =+F20*0.05 -> 49706.816 | J20: =+F20*0.025 -> 24853.408 | M20: =+F20-I20-J20-L20 -> 919576.1 | N20: =+M20 -> 919576.1 | O20: 46163 | Q20: 16 | R20: =+'Básico $'!F20 -> 14998517 | S20: =+F20/R20 -> 0.06628231 | T20: =+S20-S19 -> 0.0034824511 | U20: 110
B21: 18 | C21: 46113 | D21: A-5477 | E21: 46173 | F21: 889962.6 | G21: =+F21*0.22 -> 195791.77 | H21: =+F21+G21 -> 1085754.4 | I21: =+F21*0.05 -> 44498.13 | J21: =+F21*0.025 -> 22249.065 | M21: =+F21-I21-J21-L21 -> 823215.41 | N21: =+M21 -> 823215.41 | O21: 46198 | Q21: 17 | R21: =+'Básico $'!F21 -> 12295338 | S21: =+F21/R21 -> 0.072382116 | T21: =+S21-S20 -> 0.0060998063 | U21: 116
B22: 19 | C22: 46143 | D22: A-5527 | E22: 46203 | F22: 1062891 | G22: =+F22*0.22 -> 233836.02 | H22: =+F22+G22 -> 1296727 | I22: =+F22*0.05 -> 53144.55 | J22: =+F22*0.025 -> 26572.275 | M22: =+F22-I22-J22-L22 -> 983174.17 | N22: 983174.17 | O22: 46233 | Q22: 18 | R22: =+'Básico $'!F22 -> 14976847 | S22: =+F22/R22 -> 0.070968945 | T22: =+S22-S21 -> -0.001413171 | U22: 123
F24: =SUM(F3:F23) -> 14041077 | G24: =SUM(G3:G23) -> 3089037 | H24: =SUM(H3:H23) -> 17130115 | I24: =SUM(I3:I23) -> 702053.87 | J24: =SUM(J3:J23) -> 351026.94 | L24: =SUM(L3:L23) -> 23604 | M24: =SUM(M3:M23) -> 12964393 | N24: =SUM(N3:N23) -> 12964394 | R24: =SUM(R3:R23) -> 2.530642e+08

Sheet AP Adicionales
B3: N° Certificado | C3: Mes certificado | D3: Factura | E3: Fecha factura | F3: Subtotal | G3: IVA | H3: Total | I3: Garantía (Retención fondo reparo) | J3: Monto a pagar | L3: Pago | M3: Fecha pago | N3: Comentario | O3: Carta IVA | P3: Monto certificado | Q3: % Ajuste | R3: Variacion | S3: OP GP | U3: Resumen
B4: AD OC 02 | C4: 45809 | D4: A-4881 | E4: 45869 | F4: 7001.87 | G4: =+F4*0.22 -> 1540.4114 | H4: =+F4+G4 -> 8542.2814 | I4: =+F4*0.05 -> 350.0935 | J4: =+F4-I4 -> 6651.7765 | K4: =+J4 -> 6651.7765 | L4: 6651.7765 | M4: 45891 | O4: 7 | P4: =+'AyD $'!F4 -> 138254.19 | Q4: =+F4/P4 -> 0.050644903 | S4: 064 | U4: Monto avanzado | V4: =+F10 -> 31354.16
B5: AD OC 03 | C5: 45809 | D5: A-4882 | E5: 45869 | F5: 37158.46 | G5: =+F5*0.22 -> 8174.8612 | H5: =+F5+G5 -> 45333.321 | I5: =+F5*0.05 -> 1857.923 | J5: =+F5-I5 -> 35300.537 | K5: =+J5 -> 35300.537 | L5: 35300.537 | M5: 45891 | O5: 7 | P5: =+'AyD $'!F5 -> 497490.6 | Q5: =+F5/P5 -> 0.074691783 | R5: =+Q5-Q4 -> 0.02404688 | S5: 064 | U5: IVA certificados | V5: =+G10 -> 6897.9152
B6: AD OC 04 | C6: 45839 | D6: A-4917 | E6: 45900 | F6: 16717.72 | G6: =+F6*0.22 -> 3677.8984 | H6: =+F6+G6 -> 20395.618 | I6: =+F6*0.05 -> 835.886 | J6: =+F6-I6 -> 15881.834 | K6: =+J6 -> 15881.834 | L6: 15882.1 | M6: 45919 | O6: 8 | P6: =+'AyD $'!F6 -> 309912 | Q6: =+F6/P6 -> 0.053943442 | R6: =+Q6-Q5 -> -0.020748341 | S6: 068 | U6: Total IVA inc | V6: =+H10 -> 38252.075
B7: AD OC 06 | C7: 46143 | D7: A-1963 | E7: 46203 | F7: -37121.11 | G7: =+F7*0.22 -> -8166.6442 | H7: =+F7+G7 -> -45287.754 | I7: =+F7*0.05 -> -1856.0555 | J7: =+F7-I7 -> -35265.054 | K7: =+J7+J8 -> -28047.695 | L7: -28048 | M7: 46233 | N7: Se descuenta de AP básico | O7: 18 | P7: =+'AyD $'!F7+'AyD $'!F8 -> -388307.41 | Q7: =(+F7+F8)/P7 -> 0.07603226 | R7: =+Q7-Q6 -> 0.022088818 | S7: ND 016 | U7: Garantía retenida | V7: =+I10 -> 1567.708
B8: AD OC 13 | D8: A-5528 | E8: 46203 | F8: 7597.22 | G8: =+F8*0.22 -> 1671.3884 | H8: =+F8+G8 -> 9268.6084 | I8: =+F8*0.05 -> 379.861 | J8: =+F8-I8 -> 7217.359 | U8: Pago | V8: =+L10 -> 29786.413
F10: =SUM(F4:F9) -> 31354.16 | G10: =SUM(G4:G9) -> 6897.9152 | H10: =SUM(H4:H9) -> 38252.075 | I10: =SUM(I4:I9) -> 1567.708 | J10: =SUM(J4:J9) -> 29786.452 | L10: =SUM(L4:L9) -> 29786.413 | M10: =SUM(M4:M9) -> 183934

Sheet Por orden GP
B2: OP GP | C2: Concepto | D2: $ | N2: USD
D3: Subtotal | E3: IVA | F3: Total | G3: Acopio 1 | H3: Acopio 2 | I3: Acopio 3 | J3: Garantía (Retención fondo reparo) | K3: Canje unidades (Retención complementaria) | L3: Aportes patronales por partidas exentas | M3: Monto a pagar | N3: Subtotal | O3: IVA | P3: Total | Q3: Acopio 1 | R3: Acopio 2 | S3: Acopio 3 | T3: Garantía (Retención fondo reparo) | U3: Canje unidades (Retención complementaria) | V3: Monto a pagar
B4: 036 | C4: Básico diciembre 2024 | D4: =+'Básico $'!F4 -> 3020726 | E4: =+'Básico $'!G4 -> 664559.72 | F4: =+'Básico $'!H4 -> 3685285.7 | G4: =+'Básico $'!I4 -> 0 | H4: =+'Básico $'!J4 -> 0 | I4: =+'Básico $'!K4 -> 0 | J4: =+'Básico $'!L4 -> 151036.3 | K4: =+'Básico $'!M4 -> 75518.15 | L4: =+'Básico $'!O4 -> 0 | M4: =+'Básico $'!P4 -> 2794171.6
B5: 038 | C5: Básico enero 2025 | D5: =+'Básico $'!F5 -> 2620526 | E5: =+'Básico $'!G5 -> 576515.72 | F5: =+'Básico $'!H5 -> 3197041.7 | G5: =+'Básico $'!I5 -> 0 | H5: =+'Básico $'!J5 -> 0 | I5: =+'Básico $'!K5 -> 0 | J5: =+'Básico $'!L5 -> 131026.3 | K5: =+'Básico $'!M5 -> 65513.15 | L5: =+'Básico $'!O5 -> 0 | M5: =+'Básico $'!P5 -> 2423986.6
B6: 040 | C6: Básico febrero 2025 | D6: =+'Básico $'!F6 -> 7539478 | E6: =+'Básico $'!G6 -> 1658685.2 | F6: =+'Básico $'!H6 -> 9198163.2 | G6: =+'Básico $'!I6 -> 0 | H6: =+'Básico $'!J6 -> 0 | I6: =+'Básico $'!K6 -> 0 | J6: =+'Básico $'!L6 -> 376973.9 | K6: =+'Básico $'!M6 -> 188486.95 | L6: =+'Básico $'!O6 -> 0 | M6: =+'Básico $'!P6 -> 6974017.1
B7: 042 | C7: Básico marzo 2025 | D7: =+'Básico $'!F7 -> 14122299 | E7: =+'Básico $'!G7 -> 3106905.8 | F7: =+'Básico $'!H7 -> 17229205 | G7: =+'Básico $'!I7 -> 0 | H7: =+'Básico $'!J7 -> 0 | I7: =+'Básico $'!K7 -> 0 | J7: =+'Básico $'!L7 -> 706114.95 | K7: =+'Básico $'!M7 -> 353057.48 | L7: =+'Básico $'!O7 -> 0 | M7: =+'Básico $'!P7 -> 13063127
B8: 045 | C8: Básico abril 2025 | D8: =+'Básico $'!F8 -> 7660122 | E8: =+'Básico $'!G8 -> 1685226.8 | F8: =+'Básico $'!H8 -> 9345348.8 | G8: =+'Básico $'!I8 -> 0 | H8: =+'Básico $'!J8 -> 0 | I8: =+'Básico $'!K8 -> 0 | J8: =+'Básico $'!L8 -> 383006.1 | K8: =+'Básico $'!M8 -> 191503.05 | L8: =+'Básico $'!O8 -> 0 | M8: =+'Básico $'!P8 -> 7085612.9
B9: 048 | C9: Acopio financiero 1 (2%) | D9: =+Acopios!E7 -> 8935691.8 | E9: 0 | F9: =+D9 -> 8935691.8 | M9: 8935691.8 | N9: =+Acopios!E8+Acopios!E9 -> 21774.14 | O9: 0 | P9: =+N9 -> 21774.14 | V9: 21774.14
B10: 051B | C10: AP diciembre 2024 | D10: =+AP!F3 -> 60057.54 | E10: =+AP!G3 -> 13212.659 | F10: =+AP!H3 -> 73270.199 | J10: =+AP!I3 -> 3002.877 | K10: =+AP!J3 -> 1501.4385 | L10: =+AP!L3 -> 1931 | M10: =+AP!M3 -> 53622.224
B11: 052B | C11: AP enero 2025 | D11: =+AP!F4 -> 57599.76 | E11: =+AP!G4 -> 12671.947 | F11: =+AP!H4 -> 70271.707 | J11: =+AP!I4 -> 2879.988 | K11: =+AP!J4 -> 1439.994 | L11: =+AP!L4 -> 821 | M11: =+AP!M4 -> 52458.778
B12: 053B | C12: AP febrero 2025 | D12: =+AP!F5 -> 210401.13 | E12: =+AP!G5 -> 46288.249 | F12: =+AP!H5 -> 256689.38 | J12: =+AP!I5 -> 10520.057 | K12: =+AP!J5 -> 5260.0283 | L12: =+AP!L5 -> 4689 | M12: =+AP!M5 -> 189932.05
B13: 054B | C13: AP marzo 2025 | D13: =+AP!F6 -> 395161.09 | E13: =+AP!G6 -> 86935.44 | F13: =+AP!H6 -> 482096.53 | J13: =+AP!I6 -> 19758.055 | K13: =+AP!J6 -> 9879.0273 | L13: =+AP!L6 -> 8187 | M13: =+AP!M6 -> 357337.01
B14: 055B | C14: AP abril 2025 | D14: =+AP!F7 -> 445592.4 | E14: =+AP!G7 -> 98030.328 | F14: =+AP!H7 -> 543622.73 | J14: =+AP!I7 -> 22279.62 | K14: =+AP!J7 -> 11139.81 | L14: =+AP!L7 -> 7976 | M14: =+AP!M7 -> 404196.97
B15: 056B | C15: Básico mayo 2025 | D15: =+'Básico $'!F9 -> 13979077 | E15: =+'Básico $'!G9 -> 3075396.9 | F15: =+'Básico $'!H9 -> 17054474 | G15: =+'Básico $'!I9 -> 303318.01 | H15: =+'Básico $'!J9 -> 0 | I15: =+'Básico $'!K9 -> 0 | J15: =+'Básico $'!L9 -> 698953.85 | K15: =+'Básico $'!M9 -> 349476.93 | L15: =+'Básico $'!O9 -> 0 | M15: =+'Básico $'!P9 -> 12627328
B16: 059 | C16: Básico junio 2025 | D16: =+'Básico $'!F10 -> 14933843 | E16: =+'Básico $'!G10 -> 3285445.6 | F16: =+'Básico $'!H10 -> 18219289 | G16: =+'Básico $'!I10 -> 324034.54 | H16: =+'Básico $'!J10 -> 0 | I16: =+'Básico $'!K10 -> 0 | J16: =+'Básico $'!L10 -> 746692.17 | K16: =+'Básico $'!M10 -> 373346.09 | L16: =+'Básico $'!O10 -> 11546 | M16: =+'Básico $'!P10 -> 13478225
B17: 061 | C17: AyD junio 2025 OC02 OC03 | D17: =+'AyD $'!F4+'AyD $'!F5 -> 635744.79 | E17: =+'AyD $'!G4+'AyD $'!G5 -> 139863.85 | F17: =+'AyD $'!H4+'AyD $'!H5 -> 775608.64 | J17: =+'AyD $'!K4 -> 4608.473 | M17: =+'AyD $'!L4+'AyD $'!L5 -> 560177.06
B18: 063 | C18: Básico julio 2025 y AP mayo y junio | D18: =+'Básico $'!F11+AP!F9+AP!F10 -> 17055903 | E18: =+'Básico $'!G11+AP!G9+AP!G10 -> 3752298.7 | F18: =+'Básico $'!H11+AP!H9+AP!H10 -> 20808202 | G18: =+'Básico $'!I11 -> 334477.69 | H18: =+'Básico $'!J11 -> 0 | I18: =+'Básico $'!K11 -> 0 | J18: =+'Básico $'!L11+AP!I9+AP!I10 -> 852795.16 | K18: =+'Básico $'!M11+AP!J9+AP!J10 -> 426397.58 | L18: =+'Básico $'!O11+AP!L9+AP!L10 -> 0 | M18: =+'Básico $'!P11+AP!M9+AP!M10 -> 15442233
B19: 064 | C19: Adicionales julio 2025 y AP adicionales junio | D19: =+'AyD $'!F6+'AP Adicionales'!F4+'AP Adicionales'!F5 -> 354072.33 | E19: =+'AyD $'!G6+'AP Adicionales'!G4+'AP Adicionales'!G5 -> 77895.913 | F19: =+'AyD $'!H6+'AP Adicionales'!H4+'AP Adicionales'!H5 -> 431968.24 | J19: =+'AyD $'!K6+'AP Adicionales'!I4+'AP Adicionales'!I5 -> 17703.617 | M19: =+'AyD $'!L6+'AP Adicionales'!J4+'AP Adicionales'!J5 -> 336368.71
B20: 067 | C20: Básico agosto 2025 y AP julio | D20: =+'Básico $'!F12+AP!F11 -> 22501352 | E20: =+'Básico $'!G12+AP!G11 -> 4950297.4 | F20: =+'Básico $'!H12+AP!H11 -> 27451649 | G20: =+'Básico $'!I12 -> 470115.29 | H20: =+'Básico $'!J12 -> 0 | I20: =+'Básico $'!K12 -> 0 | J20: =+'Básico $'!L12+AP!I11 -> 1125067.6 | K20: =+'Básico $'!M12+AP!J11 -> 562533.79 | L20: =+'Básico $'!O12+AP!L11 -> 28774 | M20: =+'Básico $'!P12+AP!M11 -> 20314861
B21: 068 | C21: AP adicionales julio 2025 | D21: =+'AP Adicionales'!F6 -> 16717.72 | E21: =+'AP Adicionales'!G6 -> 3677.8984 | F21: =+'AP Adicionales'!H6 -> 20395.618 | J21: =+'AP Adicionales'!I6 -> 835.886 | M21: =+'AP Adicionales'!J6 -> 15881.834
B22: 071 (ND 01) | C22: Básico septiembre y AP agosto - aportes patronales | D22: 22122654 | E22: 4870250.4 | F22: =+D22+E22 -> 26992904 | G22: =+'Básico $'!I13 -> 455237.78 | H22: =+'Básico $'!J13 -> 0 | I22: =+'Básico $'!K13 -> 0 | J22: =+'Básico $'!L13+AP!I12 -> 1106875.1 | K22: =+'Básico $'!M13+AP!J12 -> 553437.55 | L22: =+'Básico $'!O13+AP!L12 -> 14848 | M22: =+'Básico $'!P13+AP!M12 -> 20007104
B23: 074 | C23: Anticipo financiero 2 | D23: =+Acopios!E12 -> 6701768.8 | E23: 0 | F23: =+D23 -> 6701768.8 | M23: =+F23 -> 6701768.8 | N23: =+Acopios!E13+Acopios!E14 -> 16330.605 | O23: 0 | P23: =+N23 -> 16330.605 | V23: =+P23 -> 16330.605
B24: 075 | C24: Anticipo ascensores etapa 2 | N24: 22293.6 | O24: 0 | P24: =+N24 -> 22293.6 | V24: 22293.6
B25: 076 (ND 02) | C25: Cerificado 11 Octubre y AP Septiembre 2025 - aportes patronales | D25: 25766012 | E25: 5672491.4 | F25: =+D25+E25 -> 31438503 | G25: =+'Básico $'!I14 -> 534817.06 | H25: 0 | I25: 0 | J25: =+'Básico $'!L14+AP!I13 -> 1289202.6 | K25: =+'Básico $'!M14+AP!J13 -> 644601.3 | L25: =+'Básico $'!O14+AP!L13 -> 18040 | M25: =+'Básico $'!P14+AP!M13+'Básico $'!F15 -> 22788884
B26: 082 (ND 03) | C26: Cerificado 12 Noviembre y AP Octubre 2025 - aportes patronales | D26: =23807290-22155 -> 23785135 | E26: 5237604 | F26: =+D26+E26 -> 29022739 | G26: =+'Básico $'!I16 -> 485378.62 | H26: =+'Básico $'!J16 -> 499382.08 | I26: =+'Básico $'!K16 -> 0 | J26: =+'Básico $'!L16+AP!I14 -> 1190364.5 | K26: =+'Básico $'!M16+AP!J14 -> 595182.23 | L26: =+'Básico $'!O16+AP!L14 -> 22155 | M26: =+'Básico $'!P16+AP!M14 -> 21014827
B27: 084 (ND 04) | C27: Certidicado 13 Diciembre - aportes patronales | D27: 17482190 | E27: 3850713 | F27: =+D27+E27 -> 21332903 | G27: =+'Básico $'!I17 -> 379785.32 | H27: =+'Básico $'!J17 -> 390742.34 | I27: =+'Básico $'!K17 -> 0 | J27: =+'Básico $'!L17 -> 875162.03 | K27: =+'Básico $'!M17 -> 437581.02 | L27: =+'Básico $'!O17 -> 21051 | M27: =+'Básico $'!P17 -> 15398919
B28: 089 | C28: AP noviembre y AP provisorio diciembre | D28: 2266032 | E28: =+D28*0.22 -> 498527.04 | F28: =+D28+E28 -> 2764559 | J28: =+AP!I15+AP!I16 -> 113301.6 | K28: =+AP!J15+AP!J16 -> 56650.799 | L28: =+AP!L15+AP!L16 -> 0 | M28: =+AP!M15+AP!M16 -> 2096079.6
B29: 091 (ND 05) | C29: Certificado 14 Enero - aportes patronales - diferencia AP definitivo diciembre | D29: 11865884 | E29: 2613744.3 | F29: =+D29+E29 -> 14479628 | G29: =+'Básico $'!I18 -> 258408.14 | H29: =+'Básico $'!J18 -> 265863.37 | I29: =+'Básico $'!K18 -> 0 | J29: =+'Básico $'!L18+AP!I17 -> 594032.75 | K29: =+'Básico $'!M18+AP!J17 -> 297016.38 | L29: =+'Básico $'!O18+AP!L17 -> 14772 | M29: =+'Básico $'!P18+AP!M17 -> 10450562
B30: 094 (ND 06) | C30: Certificado 15 febrero y AP enero | D30: =13126082-14060 -> 13112022 | E30: =+D30*0.22 -> 2884644.8 | F30: =+D30+E30 -> 15996667 | G30: =+'Básico $'!I19 -> 269594.37 | H30: =+'Básico $'!J19 -> 277372.33 | I30: =+'Básico $'!K19 -> 0 | J30: =+'Básico $'!L19+AP!I18 -> 656304.1 | K30: =+'Básico $'!M19+AP!J18 -> 328152.05 | L30: =+'Básico $'!O19+AP!L18 -> 14060 | M30: =+'Básico $'!P19+AP!M18 -> 11580599
B31: 102 | C31: Anticipo financiero 3 | D31: 6701768.8 | E31: 0 | F31: =+D31 -> 6701768.8 | M31: =+F31 -> 6701768.8 | N31: 16330.605 | O31: 0 | P31: =+N31 -> 16330.605 | V31: =+P31 -> 16330.605
B32: 105 (ND 07) | C32: Certificado 16 marzo 2026 $ y AP febrero | D32: =15778796-17553 -> 15761243 | E32: 3471335 | F32: =+D32+E32 -> 19232578 | G32: =+'Básico $'!I20 -> 325437.81 | H32: =+'Básico $'!J20 -> 334826.88 | I32: =+'Básico $'!K20 -> 425927.87 | J32: =+'Básico $'!L20+AP!I19 -> 788939.77 | K32: =+'Básico $'!M20+AP!J19 -> 394469.88 | L32: =+'Básico $'!O20 -> 17553 | M32: =+'Básico $'!P20+AP!M19 -> 13491640
B33: 106 | C33: Certificado 2 marzo 2026 USD plaza | N33: 20074.19 | O33: =+N33*0.22 -> 4416.3218 | P33: =+N33+O33 -> 24490.512 | Q33: =+'Básico USD Plaza'!I5 -> 401.4848 | R33: =+'Básico USD Plaza'!J5 -> 301.1136 | S33: =+'Básico USD Plaza'!K5 -> 309.40182 | T33: =+'Básico USD Plaza'!L5 -> 1003.712 | U33: =+'Básico USD Plaza'!M5 -> 501.856 | V33: =+'Básico USD Plaza'!N5 -> 17556.672
B34: 107 (ND 08B) | C34: Certificado 1 marzo 2026 USD CIF - AyD 1 USD CIF | N34: =89319.97-88764.77 -> 555.2 | O34: 0 | P34: =+N34 -> 555.2 | Q34: =+'Básico USD CIF'!I4 -> 1786.4 | R34: =+'Básico USD CIF'!J4 -> 1339.8 | S34: =+'Básico USD CIF'!K4 -> 1339.8 | T34: =+'Básico USD CIF'!L4+'AYD USD CIF'!J4 -> 27.761695 | U34: =+'Básico USD CIF'!M4 -> 2233 | V34: =+N34-Q34-R34-S34-T34-U34-L34 -> -6171.5617 | W34: =+V34+V35+V36+V37 -> 78154.97 | X34: Se paga todo junto
B35: 108 | C35: AyD 1 USD Plaza | N35: 88764.77 | O35: =+N35*0.22 -> 19528.249 | P35: =+N35+O35 -> 108293.02 | T35: =+'AYD USD Plaza '!J4 -> 4438.2383 | V35: =+N35-Q35-R35-S35-T35-U35 -> 84326.532
B36: ND 09 | C36: Complemento 08B - Certificado 1 marzo 2026 Aumentos y Disminuciones USD CIF (adm de subcontratos) | N36: -555.2 | O36: 0 | P36: =+N36 -> -555.2 | T36: =+'AYD USD CIF'!J5 -> -27.759954 | V36: =+N36-T36 -> -527.44005
B37: 109 | C37: Complemento 108 - Certificado 1 marzo 2026 Aumentos y Disminuciones USD Plaza (adm de subcontratos) | N37: 555.2 | O37: =+N37*0.22 -> 122.144 | P37: =+N37+O37 -> 677.344 | T37: =+'AYD USD Plaza '!J5 -> 27.759954 | V37: =+N37-T37 -> 527.44005
B38: 110 (010) | C38: Certificado 17 abril $ y AP marzo | D38: 13289475 | E38: =+D38*0.22 -> 2923684.5 | F38: =+D38+E38 -> 16213160 | G38: =+'Básico $'!I21 -> 266784.25 | H38: =+'Básico $'!J21 -> 274481.13 | I38: =+'Básico $'!K21 -> 349163.02 | J38: =+'Básico $'!L21+AP!I20 -> 664473.73 | K38: =+'Básico $'!M21+AP!J20 -> 332236.86 | L38: =+'Básico $'!O21+AP!L20 -> 19349 | M38: =+'Básico $'!P21+AP!M20 -> 11382987
B39: 111 | C39: Certificado 3 abril USD plaza | N39: =+'Básico USD Plaza'!F6 -> 36286.38 | O39: =+'Básico USD Plaza'!G6 -> 7983.0036 | P39: =+'Básico USD Plaza'!H6 -> 44269.384 | Q39: =+'Básico USD Plaza'!I6 -> 725.7276 | R39: =+'Básico USD Plaza'!J6 -> 544.2957 | S39: =+'Básico USD Plaza'!K6 -> 559.27756 | T39: =+'Básico USD Plaza'!L6 -> 1814.319 | U39: =+'Básico USD Plaza'!M6 -> 907.1595 | V39: =+'Básico USD Plaza'!N6 -> 31735.601
B40: 112 (ND 011) | C40: Certificado 2 abril 2026 USD CIF - AyD 2 USD CIF | N40: =2157.01-2157.01 -> 0 | O40: 0 | P40: =+N40 -> 0 | Q40: =+'Básico USD CIF'!I5 -> 43.1402 | R40: =+'Básico USD CIF'!J5 -> 32.35515 | S40: =+'Básico USD CIF'!K5 -> 32.35515 | T40: =+'Básico USD CIF'!L5+'AYD USD CIF'!J6+'AYD USD CIF'!J7 -> -0.0030450773 | U40: =+'Básico USD CIF'!M5 -> 53.92525 | V40: =+'Básico USD CIF'!N5+'AYD USD CIF'!K6+'AYD USD CIF'!K7 -> -161.83361 | W40: =+V40+V41 -> 1887.3838 | X40: Se paga todo junto
B41: 113 | C41: AyD 2 USD Plaza | N41: =+'AYD USD Plaza '!I6+'AYD USD Plaza '!I7 -> 2157.0709 | O41: =+N41*0.22 -> 474.5556 | P41: =+N41+O41 -> 2631.6265 | Q41: 0 | R41: 0 | S41: 0 | T41: =+'AYD USD Plaza '!J6+'AYD USD Plaza '!J7 -> 107.85355 | U41: 0 | V41: =+'AYD USD Plaza '!K6+'AYD USD Plaza '!K7 -> 2049.2174
...

Sheet Ascensores
